-- Error: tests/neg-custom-args/captures/exception-definitions.scala:3:8 -----------------------------------------------
3 |  self: Err^ => // error
  |        ^^^^
  |reference (caps.cap : caps.Capability) captured by this self type is not included in the allowed capture set {} of pure base class class Throwable
-- Error: tests/neg-custom-args/captures/exception-definitions.scala:7:12 ----------------------------------------------
7 |    val x = c  // error
  |            ^
  |            reference (c : Any^) is not included in the allowed capture set {} of the self type of class Err2
-- Error: tests/neg-custom-args/captures/exception-definitions.scala:8:13 ----------------------------------------------
8 |  class Err3(c: Any^) extends Exception // error
  |             ^
  |       reference (Err3.this.c : Any^) is not included in the allowed capture set {} of the self type of class Err3
